Workbook
Name Master1: #REF!
Name MasterTAble: Master!$A$1:$K$187

Sheet Master
A1: Фирма | C1: СТАТУС | D1: MAND | E1: Счетоводител | F1: Заместване | G1: ТРЗ | H1: ХОНОРАР | I1: ТРЗ Отг. | J1: ТРЗ Статус | K1: Данък изт./СИДО
A2: 2Б ООД | C2: АКТИВНА | D2: NULA | E2: АНУШКА РАДЕВА | F2: ВИОЛИНА МИТАКСОВА | G2: АТАНАСКА ГОСПОДИНОВА | H2: 0 | I2: АТАНАСКА ГОСПОДИНОВА | J2: СОЛ | K2: НЕ
A3: АВОМИС ЕООД | B3: Ок | C3: АКТИВНА | D3: NULA | E3: АНУШКА РАДЕВА | F3: КРАСИМИРА ГЕОРГИЕВА | H3: 0 | I3: АТАНАСКА ГОСПОДИНОВА | J3: ДУК | Q3: =PayRoll!A2 -> АНГЕЛ ТОДОРОВ | R3: =PayRoll!H2 -> 1413.2 | S3: =SUMIF(E:E,Q3,H:H) -> 200
A4: АГРИ СТРОЙ ЕООД | B4: Ок | C4: АКТИВНА | D4: 257 | E4: МАЯ МАТАНСКА | F4: ВИОЛИНА МИТАКСОВА | H4: 0 | Q4: =PayRoll!A3 -> АНЕЛИЯ ПЕНКОВА | R4: =PayRoll!H3 -> 1413.2 | S4: =SUMIF(E:E,Q4,H:H) -> 0
A5: АГРОГРУП 2017 ООД | B5: Ок | C5: АКТИВНА | D5: NULA | F5: ВИОЛИНА МИТАКСОВА | H5: 150 | M5: Ок | Q5: =PayRoll!A4 -> АНЕЛИЯ ЩЕРЕВА | R5: =PayRoll!H4 -> 0 | S5: =SUMIF(E:E,Q5,H:H) -> 0
A6: АГРОДЕН ООД | B6: Ок | C6: АКТИВНА | D6: 358 | F6: КРАСИМИРА ГЕОРГИЕВА | H6: 700 | I6: СИЛВИЯ ИВАНОВА | J6: СОЛ+ | M6: Проблемен | Q6: =PayRoll!A5 -> АТАНАСКА ГОСПОДИНОВА | R6: =PayRoll!H5 -> 1613.2 | S6: =SUMIF(E:E,Q6,H:H) -> 0
A7: АДВАНС ХОУМС ООД | B7: Ок | C7: АКТИВНА | D7: NULA | F7: РАДКА НИКОЛОВА | H7: 250 | I7: АТАНАСКА ГОСПОДИНОВА | J7: А1 | M7: Изискващ | Q7: =PayRoll!A6 -> АНУШКА РАДЕВА | R7: =PayRoll!H6 -> 1200 | S7: =SUMIF(E:E,Q7,H:H) -> 3180
A8: АДВОКАТСКО СЪДРУЖИЕ ЗЛАТКОВА И БРЕЗОВСКА | B8: Ок | C8: АКТИВНА | D8: 465 | E8: ПЕТЯ ПАВЛОВА | F8: РАДКА НИКОЛОВА | H8: 250 | I8: АТАНАСКА ГОСПОДИНОВА | J8: СОЛ | M8: Обемен | Q8: =PayRoll!A7 -> ВИОЛИНА МИТАКСОВА | R8: =PayRoll!H7 -> 1693.2 | S8: =SUMIF(E:E,Q8,H:H) -> 0
A9: АДРИАТИКА БЛУ ЕООД | B9: Ок | C9: АКТИВНА | D9: NULA | E9: ПЕТЯ ПАВЛОВА | F9: ВИОЛИНА МИТАКСОВА | H9: 800 | I9: СИЛВИЯ ИВАНОВА | J9: ДУК+ | Q9: =PayRoll!A8 -> ГАЛИНА ГЕОРГИЕВА | R9: =PayRoll!H8 -> 1363.2 | S9: =SUMIF(E:E,Q9,H:H) -> 7250
A10: АКВА КРАФТ ЕООД | C10: НУЛЕВО | D10: 281 | E10: АНУШКА РАДЕВА | F10: РАДКА НИКОЛОВА | H10: 0 | Q10: =PayRoll!A9 -> ДИМИТРИНА КОЛЕВА | R10: =PayRoll!H9 -> 1588.2 | S10: =SUMIF(E:E,Q10,H:H) -> 0
A11: АЛЕКС К 2002 ЕООД | B11: Изискващ | C11: АКТИВНА | D11: NULA | E11: ГАЛИНА ГЕОРГИЕВА | F11: КРАСИМИРА ГЕОРГИЕВА | H11: 1100 | I11: АТАНАСКА ГОСПОДИНОВА | J11: ДУК+ | Q11: =PayRoll!A10 -> КРАСИМИРА ГЕОРГИЕВА | R11: =PayRoll!H10 -> 1693.2 | S11: =SUMIF(E:E,Q11,H:H) -> 0
A12: ВЕК ТРЕЙДИНГ ООД | B12: Проблемен | C12: АКТИВНА | D12: 010 | E12: МАЯ МАТАНСКА | F12: ВИОЛИНА МИТАКСОВА | H12: 700 | I12: АТАНАСКА ГОСПОДИНОВА | J12: СОЛ+ | Q12: =PayRoll!A11 -> МАРИЯ МОНЧЕВСКА | R12: =PayRoll!H11 -> 1663.2 | S12: =SUMIF(E:E,Q12,H:H) -> 0
A13: АЛИСА 34 ЕООД | C13: НУЛЕВО | D13: 296 | E13: АНУШКА РАДЕВА | F13: РАДКА НИКОЛОВА | H13: 0 | Q13: =PayRoll!A12 -> МАЯ МАТАНСКА | R13: =PayRoll!H12 -> 1200 | S13: =SUMIF(E:E,Q13,H:H) -> 4300
A14: АЛФА БЕТА БИЛД ООД | E14: АНГЕЛ ТОДОРОВ | H14: 200 | Q14: =PayRoll!A13 -> ПЕТЯ ПАВЛОВА | R14: =PayRoll!H13 -> 1463.2 | S14: =SUMIF(E:E,Q14,H:H) -> 0
A15: ГРИЙН ХОУМС ЕООД | B15: Проблемен | C15: НУЛЕВО | E15: АНУШКА РАДЕВА | F15: КРАСИМИРА ГЕОРГИЕВА | H15: 0 | Q15: =PayRoll!A14 -> РАДКА НИКОЛОВА | R15: =PayRoll!H14 -> 2350.6916 | S15: =SUMIF(E:E,Q15,H:H) -> 1700
A16: КОНСТРУКТ СТРОЙ ООД | B16: Проблемен | C16: НУЛЕВО | D16: 241 | E16: АНУШКА РАДЕВА | F16: РАДКА НИКОЛОВА | H16: 0 | Q16: =PayRoll!A15 -> СИЛВИЯ СТОЯНЧЕВА | R16: =PayRoll!H15 -> 1513.2 | S16: =SUMIF(E:E,Q16,H:H) -> 0
A17: ПЕРЛАИНВЕСТ ООД | B17: Изискващ | C17: АКТИВНА | D17: NULA | F17: КРАСИМИРА ГЕОРГИЕВА | H17: 1600 | I17: АТАНАСКА ГОСПОДИНОВА | J17: ДУК+ | Q17: =PayRoll!A16 -> СИЛВИЯ ИВАНОВА | R17: =PayRoll!H16 -> 1463.2 | S17: =SUMIF(E:E,Q17,H:H) -> 0
A18: ПЛАМА СОФТ ООД | B18: Изискващ | C18: АКТИВНА | D18: NULA | F18: ВИОЛИНА МИТАКСОВА | H18: 880 | I18: АТАНАСКА ГОСПОДИНОВА | J18: СОЛ+ | R18: =SUM(R3:R17) -> 21630.892
A19: АРИМА КОНСУЛТ ООД | C19: НУЛЕВО | D19: 438 | E19: АНУШКА РАДЕВА | F19: РАДКА НИКОЛОВА | H19: 0
A20: АРТИСЕТ ООД | C20: НУЛЕВО | D20: 400 | E20: АНУШКА РАДЕВА | F20: РАДКА НИКОЛОВА | H20: 0
A21: АСЕТ ИНВЕСТМЪНТ ЕООД | C21: НУЛЕВО | E21: АНУШКА РАДЕВА | F21: КРАСИМИРА ГЕОРГИЕВА | H21: 0
A22: АСЕТ ФАРМА ЕООД | C22: НУЛЕВО | E22: АНУШКА РАДЕВА | F22: КРАСИМИРА ГЕОРГИЕВА | H22: 0
A23: АСИ 75 | C23: НУЛЕВО | D23: 172 | E23: АНУШКА РАДЕВА | F23: РАДКА НИКОЛОВА | H23: 0
A24: БОНАФАЙД ЕООД | C24: НУЛЕВО | D24: 425 | E24: АНУШКА РАДЕВА | F24: РАДКА НИКОЛОВА | H24: 0
A25: БОРЕ ГРУП ЕООД | B25: Обемен | C25: АКТИВНА | D25: 468 | F25: КРАСИМИРА ГЕОРГИЕВА | H25: 1500 | I25: АТАНАСКА ГОСПОДИНОВА | J25: ДУК+
A26: БРАТЯ ДИМОВИ 2009 ООД | B26: Ок | C26: АКТИВНА | D26: NULA | E26: АНУШКА РАДЕВА | F26: ВИОЛИНА МИТАКСОВА | H26: 400 | I26: АТАНАСКА ГОСПОДИНОВА | J26: СОЛ
A27: ВАИС ГРУП 77 ЕООД | B27: Ок | C27: АКТИВНА | D27: NULA | E27: ГАЛИНА ГЕОРГИЕВА | F27: КРАСИМИРА ГЕОРГИЕВА | H27: 0
A28: ВАЛСПОРТ 84 ЕООД | B28: Ок | C28: АКТИВНА | D28: NULA | E28: АНУШКА РАДЕВА | F28: КРАСИМИРА ГЕОРГИЕВА | H28: 200 | I28: АТАНАСКА ГОСПОДИНОВА | J28: СОЛ+
A29: ВАТЕРПОЛО КОМЕРС ЕООД | B29: Ок | C29: АКТИВНА | D29: NULA | F29: ВИОЛИНА МИТАКСОВА | H29: 100
A30: ПРЕКОС ООД | B30: Изискващ | C30: АКТИВНА | D30: 036 | F30: ВИОЛИНА МИТАКСОВА | H30: 850 | I30: АТАНАСКА ГОСПОДИНОВА | J30: ДУК+
A31: ВЕКО СТРОЙ 2009 ЕООД | C31: АКТИВНА | D31: 085 | E31: МАЯ МАТАНСКА | F31: ВИОЛИНА МИТАКСОВА | H31: 0 | I31: АТАНАСКА ГОСПОДИНОВА | J31: СОЛ
A32: ВИКИ 2 ООД | B32: Ок | C32: АКТИВНА | D32: NULA | E32: АНУШКА РАДЕВА | F32: ВИОЛИНА МИТАКСОВА | H32: 300 | I32: АТАНАСКА ГОСПОДИНОВА | J32: СОЛ+
A33: ВИКИВАТ ООД | B33: Обемен | C33: АКТИВНА | D33: 467 | E33: МАЯ МАТАНСКА | F33: КРАСИМИРА ГЕОРГИЕВА | H33: 800 | I33: СИЛВИЯ ИВАНОВА | J33: СОЛ+
A34: ВИЛХЕЛМ БЪЛГАРИЯ ЕООД | B34: Ок | C34: АКТИВНА | D34: NULA | F34: КРАСИМИРА ГЕОРГИЕВА | H34: 210 | I34: АТАНАСКА ГОСПОДИНОВА | J34: Служители
A35: РЕТУР 07 ЕООД | B35: Проблемен | C35: АКТИВНА | D35: 056 | F35: ВИОЛИНА МИТАКСОВА | H35: 500 | I35: АТАНАСКА ГОСПОДИНОВА | J35: ДУК+
A36: ВОМИС КОНСУЛТ ООД | B36: Ок | C36: АКТИВНА | D36: NULA | E36: АНУШКА РАДЕВА | F36: КРАСИМИРА ГЕОРГИЕВА | H36: 0 | I36: АТАНАСКА ГОСПОДИНОВА | J36: СОЛ+
A37: ГЕЗЕДЖИ ООД | C37: НУЛЕВО | D37: 451 | E37: АНУШКА РАДЕВА | F37: РАДКА НИКОЛОВА | H37: 0
A38: ГЕРИ МУР 2016 ЕООД | B38: Обемен | C38: АКТИВНА | D38: 277 | F38: КРАСИМИРА ГЕОРГИЕВА | H38: 1000 | I38: АТАНАСКА ГОСПОДИНОВА | J38: СОЛ+
A39: ГЛИТ ЦРО ЕООД | B39: Ок | C39: АКТИВНА | D39: NULA | E39: ДИМИТРИНА КОЛЕВА | F39: ВИОЛИНА МИТАКСОВА | H39: 500 | I39: АТАНАСКА ГОСПОДИНОВА | J39: ДУК
A40: ГРАФИС ООД | B40: Ок | C40: АКТИВНА | D40: NULA | E40: АНУШКА РАДЕВА | F40: ВИОЛИНА МИТАКСОВА | H40: 200 | I40: АТАНАСКА ГОСПОДИНОВА | J40: ДУК
...

Sheet PayRoll
A1: Име, презиме, фамилия | B1: Нето | C1: Осиг. доход | D1: Осигуровки работодател | E1: Чисто по банка | F1: КЕШ | G1: Тотал | H1: Пълен Разход | I1: 0.1892 | J1: =COUNTA(A2:A21) -> 15
A2: АНГЕЛ ТОДОРОВ | B2: 1000 | C2: 1000 | D2: =C2*$I$1 -> 189.2 | E2: 776 | F2: =B2-E2 -> 224 | G2: =C2+D2 -> 1189.2 | H2: =G2+F2 -> 1413.2
A3: АНЕЛИЯ ПЕНКОВА | B3: 1000 | C3: 1000 | D3: =C3*$I$1 -> 189.2 | E3: 776 | F3: =B3-E3 -> 224 | G3: =C3+D3 -> 1189.2 | H3: =G3+F3 -> 1413.2
A4: АНЕЛИЯ ЩЕРЕВА | B4: 800 | C4: 700 | D4: =C4*$I$1 -> 132.44 | E4: 544 | F4: =B4-E4 -> 256 | G4: =C4+D4 -> 832.44
A5: АТАНАСКА ГОСПОДИНОВА | B5: 1200 | C5: 1000 | D5: =C5*$I$1 -> 189.2 | E5: 776 | F5: =B5-E5 -> 424 | G5: =C5+D5 -> 1189.2 | H5: =G5+F5 -> 1613.2
A6: АНУШКА РАДЕВА | B6: 1200 | C6: 0 | D6: =C6*$I$1 -> 0 | E6: 0 | F6: =B6-E6 -> 1200 | G6: =C6+D6 -> 0 | H6: 1200
A7: ВИОЛИНА МИТАКСОВА | B7: 1280 | C7: 1000 | D7: =C7*$I$1 -> 189.2 | E7: 776 | F7: =B7-E7 -> 504 | G7: =C7+D7 -> 1189.2 | H7: =G7+F7 -> 1693.2
A8: ГАЛИНА ГЕОРГИЕВА | B8: 950 | C8: 1000 | D8: =C8*$I$1 -> 189.2 | E8: 776 | F8: =B8-E8 -> 174 | G8: =C8+D8 -> 1189.2 | H8: =G8+F8 -> 1363.2
A9: ДИМИТРИНА КОЛЕВА | B9: 1175 | C9: 1000 | D9: =C9*$I$1 -> 189.2 | E9: 776 | F9: =B9-E9 -> 399 | G9: =C9+D9 -> 1189.2 | H9: =G9+F9 -> 1588.2
A10: КРАСИМИРА ГЕОРГИЕВА | B10: 1280 | C10: 1000 | D10: =C10*$I$1 -> 189.2 | E10: 776 | F10: =B10-E10 -> 504 | G10: =C10+D10 -> 1189.2 | H10: =G10+F10 -> 1693.2
A11: МАРИЯ МОНЧЕВСКА | B11: 1250 | C11: 1000 | D11: =C11*$I$1 -> 189.2 | E11: 776 | F11: =B11-E11 -> 474 | G11: =C11+D11 -> 1189.2 | H11: =G11+F11 -> 1663.2
A12: МАЯ МАТАНСКА | B12: 1200 | C12: 0 | D12: =C12*$I$1 -> 0 | E12: 0 | F12: =B12-E12 -> 1200 | G12: =C12+D12 -> 0 | H12: =G12+F12 -> 1200
A13: ПЕТЯ ПАВЛОВА | B13: 1050 | C13: 1000 | D13: =C13*$I$1 -> 189.2 | E13: 776 | F13: =B13-E13 -> 274 | G13: =C13+D13 -> 1189.2 | H13: =G13+F13 -> 1463.2
A14: РАДКА НИКОЛОВА | B14: 1533.88 | C14: 1976.7 | D14: =C14*$I$1 -> 373.99164 | E14: 1533.88 | F14: =B14-E14 -> 0 | G14: =C14+D14 -> 2350.6916 | H14: =G14+F14 -> 2350.6916
A15: СИЛВИЯ СТОЯНЧЕВА | B15: 1100 | C15: 1000 | D15: =C15*$I$1 -> 189.2 | E15: 776 | F15: =B15-E15 -> 324 | G15: =C15+D15 -> 1189.2 | H15: =G15+F15 -> 1513.2
A16: СИЛВИЯ ИВАНОВА | B16: 1050 | C16: 1000 | D16: =C16*$I$1 -> 189.2 | E16: 776 | F16: =B16-E16 -> 274 | G16: =C16+D16 -> 1189.2 | H16: =G16+F16 -> 1463.2
F17: =SUBTOTAL(109,Table3[КЕШ]) -> 6455 | H17: =SUBTOTAL(109,Table3[Пълен Разход]) -> 21630.892

Sheet External Expenses
A1: Име, презиме, фамилия | B1: Нето | C1: Осиг. доход | D1: Осигуровки работодател | E1: Чисто по банка | F1: КЕШ | G1: Тотал | H1: Пълен Разход | J1: 0.1892
A2: ЛАСАРА МОРЕНО | B2: 482 | C2: 620.2 | D2: =Table4[[#This Row],[Осиг. доход ]]*$J$1 -> 117.34184 | E2: 482 | G2: =C2+D2 -> 737.54184 | H2: =G2+F2 -> 737.54184 | J2: =COUNTA(A2:A21) -> 6
A3: ДЕЙЛИС РОМЕРО ЕЧАВАРИЯ | B3: =B2 -> 482 | C3: =C2 -> 620.2 | D3: =D2 -> 117.34184 | E3: =E2 -> 482 | F3: =F2 -> 0 | G3: =G2 -> 737.54184 | H3: 0 | J3: 230
A4: НИКОЛ ДАНАИЛОВА ДИЕВА | B4: 482 | C4: 620.2 | D4: =Table4[[#This Row],[Осиг. доход ]]*$J$1 -> 117.34184 | E4: 482 | F4: 0 | G4: =C4+D4 -> 737.54184 | H4: =G4+F4 -> 737.54184
A5: РОСИЦА ДИЕВА САРЕЛСКА | B5: 2500 | C5: 1041 | D5: =Table4[[#This Row],[Осиг. доход ]]*$J$1 -> 196.9572 | E5: 808 | F5: 0 | G5: =C5+D5 -> 1237.9572 | H5: =G5+F5 -> 1237.9572
A6: САБИНА ПЕХЛИВАНОВА ДИЕВА | B6: 2500 | D6: =Table4[[#This Row],[Нето]]*10% -> 250 | E6: 2500 | G6: =C6+D6 -> 250 | H6: =G6+E6 -> 2750
A7: КАЛИН ДИЕВ | B7: 5000 | C7: 2111.64 | D7: =Table4[[#This Row],[Осиг. доход ]]*$J$1 -> 399.52229 | E7: 5000 | G7: 1250 | H7: =G7+E7 -> 6250
H8: =SUBTOTAL(109,Table4[Пълен Разход]) -> 11713.041

Sheet Segment Costs
A1: Име | B1: Отдел | C1: Сума
A2: АНГЕЛ САШЕВ ТОДОРОВ | B2: Acc | C2: 1413.2
A3: АНЕЛИЯ ТОДОРОВА ПЕНКОВА | B3: Admin | C3: 1413.2
A4: АНЕЛИЯ ТОДОРОВА ЩЕРЕВА | B4: Acc | C4: 1088.44
A5: АТАНАСКА КОЛЕВА ГОСПОДИНОВА | B5: HR | C5: 1613.2
A6: ВИОЛИНА ПЛАМЕНОВА МИТАКСОВА | B6: Acc | C6: 1693.2
A7: ГАЛИНА БОРИСЛАВОВА ГЕОРГИЕВА | B7: Acc | C7: 1363.2
A8: ДИМИТРИНА ВИТКОВА КОЛЕВА | B8: Acc | C8: 1588.2
A9: КРАСИМИРА БОРИСЛАВОВА ГЕОРГИЕВА | B9: Acc | C9: 1693.2
A10: МАРИЯ ИЛИЕВА МОНЧЕВСКА | B10: HR | C10: 1663.2
A11: МАЯ МАТАНСКА | B11: Acc | C11: 1200
A12: ПЕТЯ ГЕОРГИЕВА ПАВЛОВА | B12: Acc | C12: 1463.2
A13: РАДКА ИВАНОВА НИКОЛОВА | B13: Acc | C13: 2350.6916
... A15: СИЛВИЯ СТОЯНЧЕВА | B15: Acc | C15: 1513.2
C16: 21519.332
A21: Acc | B21: =SUMIF(Table1[Отдел],"Acc",Table1[Сума]) -> 15366.532
A22: HR | B22: =SUMIF(Table1[Отдел],"HR",Table1[Сума]) -> 4739.6
A23: Admin | B23: =SUMIF(Table1[Отдел],"Admin",Table1[Сума]) -> 1413.2

Sheet Cashfllow
A2: Income | B2: =Master!H188 -> 46520
A3: Cash | B3: 3000
A5: Payroll | B5: =Table3[[#Totals],[Пълен Разход]] -> 21630.892
A6: External | B6: =Table4[[#Totals],[Пълен Разход]] -> 11713.041
A7: Food | B7: =(PayRoll!J1+'External Expenses'!J2)*102 -> 2142
A8: Rents/Property Hub | B8: 6000
A10: Operational | B10: =SUM(B11:B16) -> 2450
A11: Интернет | B11: 100
A12: Слак | B12: 300
A13: Майкрософт | B13: 500
A14: Мобилни | B14: 1000
A15: СОТ | B15: 50
A16: Материали | B16: 500
A19: Total Expenses | B19: =B5+B6+B7+B8+B10 -> 43935.933
A22: TOTAL | B22: =(B2+B3)-B19 -> 5584.0675

Sheet Lists
D3: Колеги | E3: ТРЗ | G3: Статус
D4: АНЕЛИЯ ЩЕРЕВА | E4: АТАНАСКА ГОСПОДИНОВА | G4: АКТИВНА
D5: АНУШКА РАДЕВА | E5: СИЛВИЯ ИВАНОВА | G5: без ДДС
D6: ВИОЛИНА МИТАКСОВА | E6: МАРИЯ МОНЧЕВСКА | G6: НЕ АКТИВНА
D7: ГАЛИНА ГЕОРГИЕВА
D8: ДИМИТРИНА КОЛЕВА
D9: КРАСИМИРА ГЕОРГИЕВА
D10: АНГЕЛ ТОДОРОВ
D11: МАЯ МАТАНСКА
D12: СИЛВИЯ СТОЯНЧЕВА
D13: ПЕТЯ ПАВЛОВА
D14: РАДКА НИКОЛОВА
